root@vm-163079:~# sudo journalctl -u gunicorn.service -f
Aug 17 05:46:04 vm-163079 gunicorn[1363127]:   File "/home/edited_we2/backend/venv/lib/python3.10/site-packages/elasticsearch/client/__init__.py", line 444, in bulk
Aug 17 05:46:04 vm-163079 gunicorn[1363127]:     return self.transport.perform_request(
Aug 17 05:46:04 vm-163079 gunicorn[1363127]:   File "/home/edited_we2/backend/venv/lib/python3.10/site-packages/elasticsearch/transport.py", line 390, in perform_request
Aug 17 05:46:04 vm-163079 gunicorn[1363127]:     raise e
Aug 17 05:46:04 vm-163079 gunicorn[1363127]:   File "/home/edited_we2/backend/venv/lib/python3.10/site-packages/elasticsearch/transport.py", line 358, in perform_request
Aug 17 05:46:04 vm-163079 gunicorn[1363127]:     status, headers_response, data = connection.perform_request(
Aug 17 05:46:04 vm-163079 gunicorn[1363127]:   File "/home/edited_we2/backend/venv/lib/python3.10/site-packages/elasticsearch/connection/http_urllib3.py", line 258, in perform_request
Aug 17 05:46:04 vm-163079 gunicorn[1363127]:     raise ConnectionError("N/A", str(e), e)
Aug 17 05:46:04 vm-163079 gunicorn[1363127]: elasticsearch.exceptions.ConnectionError: ConnectionError(<urllib3.connection.HTTPConnection object at 0x7f8fbd12b850>: Failed to establish a new connection: [Errno 111] Connection refused) caused by: NewConnectionError(<urllib3.connection.HTTPConnection object at 0x7f8fbd12b850>: Failed to establish a new connection: [Errno 111] Connection refused)
Aug 17 05:46:04 vm-163079 gunicorn[1363127]:  - - [17/Aug/2025:05:46:04 +0000] "POST /api/website/v1/channels/channel/ HTTP/1.0" 500 307699 "https://social.me2we2.com/new-chanel" "Mozilla/5.0 (Windows NT 10.0; Win64; x64) AppleWebKit/537.36 (KHTML, like Gecko) Chrome/138.0.0.0 Safari/537.36"
Aug 17 09:18:53 vm-163079 gunicorn[1363126]:  - - [17/Aug/2025:09:18:53 +0000] "POST /api/website/v1/accounts/user/create/ HTTP/1.0" 201 80 "https://social.me2we2.com/signup" "Mozilla/5.0 (Windows NT 10.0; Win64; x64) AppleWebKit/537.36 (KHTML, like Gecko) Chrome/138.0.0.0 Safari/537.36"
Aug 17 09:18:56 vm-163079 gunicorn[1363126]:  - - [17/Aug/2025:09:18:56 +0000] "POST /api/website/v1/accounts/profile/create/ HTTP/1.0" 201 47 "https://social.me2we2.com/signup" "Mozilla/5.0 (Windows NT 10.0; Win64; x64) AppleWebKit/537.36 (KHTML, like Gecko) Chrome/138.0.0.0 Safari/537.36"
Aug 17 09:19:01 vm-163079 gunicorn[1363127]:  - - [17/Aug/2025:09:19:01 +0000] "POST /api/website/v1/accounts/user-detail/create/ HTTP/1.0" 201 46 "https://social.me2we2.com/signup" "Mozilla/5.0 (Windows NT 10.0; Win64; x64) AppleWebKit/537.36 (KHTML, like Gecko) Chrome/138.0.0.0 Safari/537.36"
Aug 17 09:19:01 vm-163079 gunicorn[1363127]:  - - [17/Aug/2025:09:19:01 +0000] "GET /api/website/v1/daily_questions/question HTTP/1.0" 301 0 "https://social.me2we2.com/insight-web" "Mozilla/5.0 (Windows NT 10.0; Win64; x64) AppleWebKit/537.36 (KHTML, like Gecko) Chrome/138.0.0.0 Safari/537.36"
Aug 17 09:19:01 vm-163079 gunicorn[1363125]:  - - [17/Aug/2025:09:19:01 +0000] "GET /api/website/v1/site_behavior/advertisement/ HTTP/1.0" 200 2 "https://social.me2we2.com/insight-web" "Mozilla/5.0 (Windows NT 10.0; Win64; x64) AppleWebKit/537.36 (KHTML, like Gecko) Chrome/138.0.0.0 Safari/537.36"
Aug 17 09:19:01 vm-163079 gunicorn[1363127]:  - - [17/Aug/2025:09:19:01 +0000] "GET /api/website/v1/site_behavior/topic/list/followed/ HTTP/1.0" 200 2 "https://social.me2we2.com/insight-web" "Mozilla/5.0 (Windows NT 10.0; Win64; x64) AppleWebKit/537.36 (KHTML, like Gecko) Chrome/138.0.0.0 Safari/537.36"
Aug 17 09:19:01 vm-163079 gunicorn[1363127]:  - - [17/Aug/2025:09:19:01 +0000] "GET /api/website/v1/daily_questions/question/ HTTP/1.0" 200 101 "https://social.me2we2.com/insight-web" "Mozilla/5.0 (Windows NT 10.0; Win64; x64) AppleWebKit/537.36 (KHTML, like Gecko) Chrome/138.0.0.0 Safari/537.36"
Aug 17 09:19:02 vm-163079 gunicorn[1363125]:  - - [17/Aug/2025:09:19:02 +0000] "GET /api/website/v1/site_behavior/topic/list/newest/?limit=3 HTTP/1.0" 200 2 "https://social.me2we2.com/insight-web" "Mozilla/5.0 (Windows NT 10.0; Win64; x64) AppleWebKit/537.36 (KHTML, like Gecko) Chrome/138.0.0.0 Safari/537.36"
Aug 17 09:19:02 vm-163079 gunicorn[1363126]:  - - [17/Aug/2025:09:19:02 +0000] "GET /api/website/v1/site_behavior/topic/list/top/?limit=3 HTTP/1.0" 200 2 "https://social.me2we2.com/insight-web" "Mozilla/5.0 (Windows NT 10.0; Win64; x64) AppleWebKit/537.36 (KHTML, like Gecko) Chrome/138.0.0.0 Safari/537.36"
Aug 17 09:19:02 vm-163079 gunicorn[1363127]:  - - [17/Aug/2025:09:19:02 +0000] "GET /api/website/v1/site_behavior/tags/trend/ HTTP/1.0" 200 2 "https://social.me2we2.com/insight-web" "Mozilla/5.0 (Windows NT 10.0; Win64; x64) AppleWebKit/537.36 (KHTML, like Gecko) Chrome/138.0.0.0 Safari/537.36"
Aug 17 09:19:13 vm-163079 gunicorn[1363127]: Internal Server Error: /api/website/v1/channels/channel/
Aug 17 09:19:13 vm-163079 gunicorn[1363127]: Traceback (most recent call last):
Aug 17 09:19:13 vm-163079 gunicorn[1363127]:   File "/home/edited_we2/backend/venv/lib/python3.10/site-packages/urllib3/connectionpool.py", line 790, in urlopen
Aug 17 09:19:13 vm-163079 gunicorn[1363127]:     response = self._make_request(
Aug 17 09:19:13 vm-163079 gunicorn[1363127]:   File "/home/edited_we2/backend/venv/lib/python3.10/site-packages/urllib3/connectionpool.py", line 536, in _make_request
Aug 17 09:19:13 vm-163079 gunicorn[1363127]:     response = conn.getresponse()
Aug 17 09:19:13 vm-163079 gunicorn[1363127]:   File "/home/edited_we2/backend/venv/lib/python3.10/site-packages/urllib3/connection.py", line 454, in getresponse
Aug 17 09:19:13 vm-163079 gunicorn[1363127]:     httplib_response = super().getresponse()
Aug 17 09:19:13 vm-163079 gunicorn[1363127]:   File "/usr/lib/python3.10/http/client.py", line 1375, in getresponse
Aug 17 09:19:13 vm-163079 gunicorn[1363127]:     response.begin()
Aug 17 09:19:13 vm-163079 gunicorn[1363127]:   File "/usr/lib/python3.10/http/client.py", line 318, in begin
Aug 17 09:19:13 vm-163079 gunicorn[1363127]:     version, status, reason = self._read_status()
Aug 17 09:19:13 vm-163079 gunicorn[1363127]:   File "/usr/lib/python3.10/http/client.py", line 287, in _read_status
Aug 17 09:19:13 vm-163079 gunicorn[1363127]:     raise RemoteDisconnected("Remote end closed connection without"
Aug 17 09:19:13 vm-163079 gunicorn[1363127]: http.client.RemoteDisconnected: Remote end closed connection without response
Aug 17 09:19:13 vm-163079 gunicorn[1363127]: During handling of the above exception, another exception occurred:
Aug 17 09:19:13 vm-163079 gunicorn[1363127]: Traceback (most recent call last):
Aug 17 09:19:13 vm-163079 gunicorn[1363127]:   File "/home/edited_we2/backend/venv/lib/python3.10/site-packages/elasticsearch/connection/http_urllib3.py", line 245, in perform_request
Aug 17 09:19:13 vm-163079 gunicorn[1363127]:     response = self.pool.urlopen(
Aug 17 09:19:13 vm-163079 gunicorn[1363127]:   File "/home/edited_we2/backend/venv/lib/python3.10/site-packages/urllib3/connectionpool.py", line 844, in urlopen
Aug 17 09:19:13 vm-163079 gunicorn[1363127]:     retries = retries.increment(
Aug 17 09:19:13 vm-163079 gunicorn[1363127]:   File "/home/edited_we2/backend/venv/lib/python3.10/site-packages/urllib3/util/retry.py", line 445, in increment
Aug 17 09:19:13 vm-163079 gunicorn[1363127]:     raise reraise(type(error), error, _stacktrace)
Aug 17 09:19:13 vm-163079 gunicorn[1363127]:   File "/home/edited_we2/backend/venv/lib/python3.10/site-packages/urllib3/util/util.py", line 38, in reraise
Aug 17 09:19:13 vm-163079 gunicorn[1363127]:     raise value.with_traceback(tb)
Aug 17 09:19:13 vm-163079 gunicorn[1363127]:   File "/home/edited_we2/backend/venv/lib/python3.10/site-packages/urllib3/connectionpool.py", line 790, in urlopen
Aug 17 09:19:13 vm-163079 gunicorn[1363127]:     response = self._make_request(
Aug 17 09:19:13 vm-163079 gunicorn[1363127]:   File "/home/edited_we2/backend/venv/lib/python3.10/site-packages/urllib3/connectionpool.py", line 536, in _make_request
Aug 17 09:19:13 vm-163079 gunicorn[1363127]:     response = conn.getresponse()
Aug 17 09:19:13 vm-163079 gunicorn[1363127]:   File "/home/edited_we2/backend/venv/lib/python3.10/site-packages/urllib3/connection.py", line 454, in getresponse
Aug 17 09:19:13 vm-163079 gunicorn[1363127]:     httplib_response = super().getresponse()
Aug 17 09:19:13 vm-163079 gunicorn[1363127]:   File "/usr/lib/python3.10/http/client.py", line 1375, in getresponse
Aug 17 09:19:13 vm-163079 gunicorn[1363127]:     response.begin()
Aug 17 09:19:13 vm-163079 gunicorn[1363127]:   File "/usr/lib/python3.10/http/client.py", line 318, in begin
Aug 17 09:19:13 vm-163079 gunicorn[1363127]:     version, status, reason = self._read_status()
Aug 17 09:19:13 vm-163079 gunicorn[1363127]:   File "/usr/lib/python3.10/http/client.py", line 287, in _read_status
Aug 17 09:19:13 vm-163079 gunicorn[1363127]:     raise RemoteDisconnected("Remote end closed connection without"
Aug 17 09:19:13 vm-163079 gunicorn[1363127]: urllib3.exceptions.ProtocolError: ('Connection aborted.', RemoteDisconnected('Remote end closed connection without response'))
Aug 17 09:19:13 vm-163079 gunicorn[1363127]: During handling of the above exception, another exception occurred:
Aug 17 09:19:13 vm-163079 gunicorn[1363127]: Traceback (most recent call last):
Aug 17 09:19:13 vm-163079 gunicorn[1363127]:   File "/home/edited_we2/backend/venv/lib/python3.10/site-packages/django/core/handlers/exception.py", line 47, in inner
Aug 17 09:19:13 vm-163079 gunicorn[1363127]:     response = get_response(request)
Aug 17 09:19:13 vm-163079 gunicorn[1363127]:   File "/home/edited_we2/backend/venv/lib/python3.10/site-packages/django/core/handlers/base.py", line 181, in _get_response
Aug 17 09:19:13 vm-163079 gunicorn[1363127]:     response = wrapped_callback(request, *callback_args, **callback_kwargs)
Aug 17 09:19:13 vm-163079 gunicorn[1363127]:   File "/home/edited_we2/backend/venv/lib/python3.10/site-packages/django/views/decorators/csrf.py", line 54, in wrapped_view
Aug 17 09:19:13 vm-163079 gunicorn[1363127]:     return view_func(*args, **kwargs)
Aug 17 09:19:13 vm-163079 gunicorn[1363127]:   File "/home/edited_we2/backend/venv/lib/python3.10/site-packages/rest_framework/viewsets.py", line 125, in view
Aug 17 09:19:13 vm-163079 gunicorn[1363127]:     return self.dispatch(request, *args, **kwargs)
Aug 17 09:19:13 vm-163079 gunicorn[1363127]:   File "/home/edited_we2/backend/venv/lib/python3.10/site-packages/rest_framework/views.py", line 509, in dispatch
Aug 17 09:19:13 vm-163079 gunicorn[1363127]:     response = self.handle_exception(exc)
Aug 17 09:19:13 vm-163079 gunicorn[1363127]:   File "/home/edited_we2/backend/venv/lib/python3.10/site-packages/rest_framework/views.py", line 469, in handle_exception
Aug 17 09:19:13 vm-163079 gunicorn[1363127]:     self.raise_uncaught_exception(exc)
Aug 17 09:19:13 vm-163079 gunicorn[1363127]:   File "/home/edited_we2/backend/venv/lib/python3.10/site-packages/rest_framework/views.py", line 480, in raise_uncaught_exception
Aug 17 09:19:13 vm-163079 gunicorn[1363127]:     raise exc
Aug 17 09:19:13 vm-163079 gunicorn[1363127]:   File "/home/edited_we2/backend/venv/lib/python3.10/site-packages/rest_framework/views.py", line 506, in dispatch
Aug 17 09:19:13 vm-163079 gunicorn[1363127]:     response = handler(request, *args, **kwargs)
Aug 17 09:19:13 vm-163079 gunicorn[1363127]:   File "/home/edited_we2/backend/venv/lib/python3.10/site-packages/rest_framework/mixins.py", line 19, in create
Aug 17 09:19:13 vm-163079 gunicorn[1363127]:     self.perform_create(serializer)
Aug 17 09:19:13 vm-163079 gunicorn[1363127]:   File "/home/edited_we2/backend/venv/lib/python3.10/site-packages/rest_framework/mixins.py", line 24, in perform_create
Aug 17 09:19:13 vm-163079 gunicorn[1363127]:     serializer.save()
Aug 17 09:19:13 vm-163079 gunicorn[1363127]:   File "/home/edited_we2/backend/venv/lib/python3.10/site-packages/rest_framework/serializers.py", line 212, in save
Aug 17 09:19:13 vm-163079 gunicorn[1363127]:     self.instance = self.create(validated_data)
Aug 17 09:19:13 vm-163079 gunicorn[1363127]:   File "/home/edited_we2/backend/core/website/api/v1/channels/serializers.py", line 14, in create
Aug 17 09:19:13 vm-163079 gunicorn[1363127]:     return super().create(validated_data)
Aug 17 09:19:13 vm-163079 gunicorn[1363127]:   File "/home/edited_we2/backend/venv/lib/python3.10/site-packages/rest_framework/serializers.py", line 962, in create
Aug 17 09:19:13 vm-163079 gunicorn[1363127]:     instance = ModelClass._default_manager.create(**validated_data)
Aug 17 09:19:13 vm-163079 gunicorn[1363127]:   File "/home/edited_we2/backend/venv/lib/python3.10/site-packages/django/db/models/manager.py", line 85, in manager_method
Aug 17 09:19:13 vm-163079 gunicorn[1363127]:     return getattr(self.get_queryset(), name)(*args, **kwargs)
Aug 17 09:19:13 vm-163079 gunicorn[1363127]:   File "/home/edited_we2/backend/venv/lib/python3.10/site-packages/django/db/models/query.py", line 453, in create
Aug 17 09:19:13 vm-163079 gunicorn[1363127]:     obj.save(force_insert=True, using=self.db)
Aug 17 09:19:13 vm-163079 gunicorn[1363127]:   File "/home/edited_we2/backend/venv/lib/python3.10/site-packages/django/db/models/base.py", line 739, in save
Aug 17 09:19:13 vm-163079 gunicorn[1363127]:     self.save_base(using=using, force_insert=force_insert,
Aug 17 09:19:13 vm-163079 gunicorn[1363127]:   File "/home/edited_we2/backend/venv/lib/python3.10/site-packages/django/db/models/base.py", line 787, in save_base
Aug 17 09:19:13 vm-163079 gunicorn[1363127]:     post_save.send(
Aug 17 09:19:13 vm-163079 gunicorn[1363127]:   File "/home/edited_we2/backend/venv/lib/python3.10/site-packages/django/dispatch/dispatcher.py", line 180, in send
Aug 17 09:19:13 vm-163079 gunicorn[1363127]:     return [
Aug 17 09:19:13 vm-163079 gunicorn[1363127]:   File "/home/edited_we2/backend/venv/lib/python3.10/site-packages/django/dispatch/dispatcher.py", line 181, in <listcomp>
Aug 17 09:19:13 vm-163079 gunicorn[1363127]:     (receiver, receiver(signal=self, sender=sender, **named))
Aug 17 09:19:13 vm-163079 gunicorn[1363127]:   File "/home/edited_we2/backend/venv/lib/python3.10/site-packages/django_elasticsearch_dsl/signals.py", line 61, in handle_save
Aug 17 09:19:13 vm-163079 gunicorn[1363127]:     registry.update(instance)
Aug 17 09:19:13 vm-163079 gunicorn[1363127]:   File "/home/edited_we2/backend/venv/lib/python3.10/site-packages/django_elasticsearch_dsl/registries.py", line 141, in update
Aug 17 09:19:13 vm-163079 gunicorn[1363127]:     doc().update(instance, **kwargs)
Aug 17 09:19:13 vm-163079 gunicorn[1363127]:   File "/home/edited_we2/backend/venv/lib/python3.10/site-packages/django_elasticsearch_dsl/documents.py", line 259, in update
Aug 17 09:19:13 vm-163079 gunicorn[1363127]:     return self._bulk(
Aug 17 09:19:13 vm-163079 gunicorn[1363127]:   File "/home/edited_we2/backend/venv/lib/python3.10/site-packages/django_elasticsearch_dsl/documents.py", line 236, in _bulk
Aug 17 09:19:13 vm-163079 gunicorn[1363127]:     return self.bulk(*args, **kwargs)
Aug 17 09:19:13 vm-163079 gunicorn[1363127]:   File "/home/edited_we2/backend/venv/lib/python3.10/site-packages/django_elasticsearch_dsl/documents.py", line 178, in bulk
Aug 17 09:19:13 vm-163079 gunicorn[1363127]:     response = bulk(client=self._get_connection(), actions=actions, **kwargs)
Aug 17 09:19:13 vm-163079 gunicorn[1363127]:   File "/home/edited_we2/backend/venv/lib/python3.10/site-packages/elasticsearch/helpers/actions.py", line 373, in bulk
Aug 17 09:19:13 vm-163079 gunicorn[1363127]:     for ok, item in streaming_bulk(client, actions, *args, **kwargs):
Aug 17 09:19:13 vm-163079 gunicorn[1363127]:   File "/home/edited_we2/backend/venv/lib/python3.10/site-packages/elasticsearch/helpers/actions.py", line 294, in streaming_bulk
Aug 17 09:19:13 vm-163079 gunicorn[1363127]:     for data, (ok, info) in zip(
Aug 17 09:19:13 vm-163079 gunicorn[1363127]:   File "/home/edited_we2/backend/venv/lib/python3.10/site-packages/elasticsearch/helpers/actions.py", line 230, in _process_bulk_chunk
Aug 17 09:19:13 vm-163079 gunicorn[1363127]:     for item in gen:
Aug 17 09:19:13 vm-163079 gunicorn[1363127]:   File "/home/edited_we2/backend/venv/lib/python3.10/site-packages/elasticsearch/helpers/actions.py", line 179, in _process_bulk_chunk_error
Aug 17 09:19:13 vm-163079 gunicorn[1363127]:     raise error
Aug 17 09:19:13 vm-163079 gunicorn[1363127]:   File "/home/edited_we2/backend/venv/lib/python3.10/site-packages/elasticsearch/helpers/actions.py", line 218, in _process_bulk_chunk
Aug 17 09:19:13 vm-163079 gunicorn[1363127]:     resp = client.bulk("\n".join(bulk_actions) + "\n", *args, **kwargs)
Aug 17 09:19:13 vm-163079 gunicorn[1363127]:   File "/home/edited_we2/backend/venv/lib/python3.10/site-packages/elasticsearch/client/utils.py", line 152, in _wrapped
Aug 17 09:19:13 vm-163079 gunicorn[1363127]:     return func(*args, params=params, headers=headers, **kwargs)
Aug 17 09:19:13 vm-163079 gunicorn[1363127]:   File "/home/edited_we2/backend/venv/lib/python3.10/site-packages/elasticsearch/client/__init__.py", line 444, in bulk
Aug 17 09:19:13 vm-163079 gunicorn[1363127]:     return self.transport.perform_request(
Aug 17 09:19:13 vm-163079 gunicorn[1363127]:   File "/home/edited_we2/backend/venv/lib/python3.10/site-packages/elasticsearch/transport.py", line 390, in perform_request
Aug 17 09:19:13 vm-163079 gunicorn[1363127]:     raise e
Aug 17 09:19:13 vm-163079 gunicorn[1363127]:   File "/home/edited_we2/backend/venv/lib/python3.10/site-packages/elasticsearch/transport.py", line 358, in perform_request
Aug 17 09:19:13 vm-163079 gunicorn[1363127]:     status, headers_response, data = connection.perform_request(
Aug 17 09:19:13 vm-163079 gunicorn[1363127]:   File "/home/edited_we2/backend/venv/lib/python3.10/site-packages/elasticsearch/connection/http_urllib3.py", line 258, in perform_request
Aug 17 09:19:13 vm-163079 gunicorn[1363127]:     raise ConnectionError("N/A", str(e), e)
Aug 17 09:19:13 vm-163079 gunicorn[1363127]: elasticsearch.exceptions.ConnectionError: ConnectionError(('Connection aborted.', RemoteDisconnected('Remote end closed connection without response'))) caused by: ProtocolError(('Connection aborted.', RemoteDisconnected('Remote end closed connection without response')))
Aug 17 09:19:13 vm-163079 gunicorn[1363127]:  - - [17/Aug/2025:09:19:13 +0000] "POST /api/website/v1/channels/channel/ HTTP/1.0" 500 311341 "https://social.me2we2.com/new-chanel" "Mozilla/5.0 (Windows NT 10.0; Win64; x64) AppleWebKit/537.36 (KHTML, like Gecko) Chrome/138.0.0.0 Safari/537.36"